*** Starting uWSGI 2.0.20 (64bit) on [Thu Apr  7 01:10:44 2022] ***
compiled with version: 9.3.0 on 06 March 2022 03:37:57
os: Linux-5.4.0-90-generic #101-Ubuntu SMP Fri Oct 15 20:00:55 UTC 2021
nodename: VM-20-8-ubuntu
machine: x86_64
clock source: unix
pcre jit disabled
detected number of CPU cores: 2
current working directory: /data/wwwroot/CSC4001_Project/Code
writing pidfile to uwsgi.pid
detected binary path: /usr/local/bin/uwsgi
chdir() to /data/wwwroot/CSC4001_Project/Code/backend/
your processes number limit is 15359
your memory page size is 4096 bytes
detected max file descriptor number: 1048576
building mime-types dictionary from file /etc/mime.types...567 entry found
lock engine: pthread robust mutexes
thunder lock: disabled (you can enable it with --thunder-lock)
uwsgi socket 0 bound to TCP address 127.0.0.1:8000 fd 3
Python version: 3.8.10 (default, Nov 26 2021, 20:14:08)  [GCC 9.3.0]
Python main interpreter initialized at 0x564389ab6d40
python threads support enabled
your server socket listen backlog is limited to 100 connections
your mercy for graceful operations on workers is 60 seconds
mapped 416880 bytes (407 KB) for 8 cores
*** Operational MODE: preforking+threaded ***
WSGI app 0 (mountpoint='') ready in 1 seconds on interpreter 0x564389ab6d40 pid: 588231 (default app)
*** uWSGI is running in multiple interpreter mode ***
spawned uWSGI master process (pid: 588231)
spawned uWSGI worker 1 (pid: 588234, cores: 2)
spawned uWSGI worker 2 (pid: 588236, cores: 2)
spawned uWSGI worker 3 (pid: 588237, cores: 2)
spawned uWSGI worker 4 (pid: 588238, cores: 2)
Internal Server Error: /index/
Traceback (most recent call last):
  File "/home/ubuntu/.local/lib/python3.8/site-packages/django/core/handlers/exception.py", line 47, in inner
    response = get_response(request)
  File "/home/ubuntu/.local/lib/python3.8/site-packages/django/core/handlers/base.py", line 181, in _get_response
    response = wrapped_callback(request, *callback_args, **callback_kwargs)
  File "/data/wwwroot/CSC4001_Project/Code/backend/./Our_project/views.py", line 74, in index
    return render(request, 'index.html')
  File "/home/ubuntu/.local/lib/python3.8/site-packages/django/shortcuts.py", line 19, in render
    content = loader.render_to_string(template_name, context, request, using=using)
  File "/home/ubuntu/.local/lib/python3.8/site-packages/django/template/loader.py", line 61, in render_to_string
    template = get_template(template_name, using=using)
  File "/home/ubuntu/.local/lib/python3.8/site-packages/django/template/loader.py", line 19, in get_template
    raise TemplateDoesNotExist(template_name, chain=chain)
django.template.exceptions.TemplateDoesNotExist: index.html
[pid: 588238|app: 0|req: 1/1] 14.145.139.178 () {46 vars in 991 bytes} [Wed Apr  6 17:10:57 2022] GET /index/ => generated 69538 bytes in 333 msecs (HTTP/1.1 500) 7 headers in 235 bytes (1 switches on core 0)
